Workbook

Sheet README
A2: BDA Screening Test — Sample Dataset
A4: This workbook contains fictional sample data for the Business & Data Analyst hiring assignment.
A5: Use this data to practice your SQL queries locally (import into any SQL tool) and to set up your Google Sheet for Section 3.
A7: Sheet Summary
A8: customers — 20 rows | customer_id, name, city, acquisition_channel, signup_date
A9: products — 10 rows | product_id, product_name, category, cost_price
A10: orders — 50 rows | order_id, customer_id, order_date, order_status, total_amount, coupon_code
A11: order_items — ~100 rows | order_id, product_id, quantity, unit_price
A12: complaints — 22 rows | complaint_id, order_id, complaint_type, raised_date, resolved_date, courier_partner
A14: Courier partners in dataset: BlueDart, Delhivery, Ekart
A15: Cities in dataset: Mumbai, Delhi, Ahmedabad, Surat, Bangalore, Chennai, Hyderabad, Pune, Kochi, Jaipur, Lucknow
A16: Acquisition channels: Google Ads, Instagram, Facebook Ads, Referral, Organic Search
... A18: Complaint types: Late Delivery, Wrong Item, Damaged Product, Missing Item

Sheet customers
A1: Table: customers | B1: 20 records · D2C health supplement company
A2: customer_id | B2: name | C2: city | D2: acquisition_channel | E2: signup_date
A3: C001 | B3: Priya Sharma | C3: Mumbai | D3: Google Ads | E3: 2023-03-15
A4: C002 | B4: Rohan Mehta | C4: Delhi | D4: Instagram | E4: 2023-04-02
A5: C003 | B5: Anita Joshi | C5: Ahmedabad | D5: Referral | E5: 2023-01-20
A6: C004 | B6: Karan Patel | C6: Surat | D6: Google Ads | E6: 2023-05-11
A7: C005 | B7: Sneha Iyer | C7: Bangalore | D7: Facebook Ads | E7: 2023-06-08
A8: C006 | B8: Vijay Nair | C8: Chennai | D8: Organic Search | E8: 2023-02-28
A9: C007 | B9: Deepa Reddy | C9: Hyderabad | D9: Instagram | E9: 2023-07-14
A10: C008 | B10: Arun Kumar | C10: Pune | D10: Referral | E10: 2023-08-01
A11: C009 | B11: Meera Pillai | C11: Kochi | D11: Google Ads | E11: 2023-09-19
A12: C010 | B12: Suresh Gupta | C12: Jaipur | D12: Facebook Ads | E12: 2023-10-05
A13: C011 | B13: Nidhi Shah | C13: Ahmedabad | D13: Organic Search | E13: 2023-11-22
... A22: C020 | B22: Farhan Sheikh | C22: Mumbai | D22: Instagram | E22: 2024-06-01

Sheet products
A1: Table: products | B1: 10 records
A2: product_id | B2: product_name | C2: category | D2: cost_price
A3: P01 | B3: Whey Protein 1kg | C3: Protein | D3: 850
A4: P02 | B4: Multivitamin 60 tabs | C4: Vitamins | D4: 320
A5: P03 | B5: Omega-3 Fish Oil 90 caps | C5: Supplements | D5: 480
A6: P04 | B6: Mass Gainer 2kg | C6: Protein | D6: 1100
A7: P05 | B7: BCAA 250g | C7: Protein | D7: 620
A8: P06 | B8: Vitamin D3 60 caps | C8: Vitamins | D8: 210
A9: P07 | B9: Pre-Workout 300g | C9: Performance | D9: 750
A10: P08 | B10: Collagen Peptides 200g | C10: Wellness | D10: 540
A11: P09 | B11: Ashwagandha 60 caps | C11: Wellness | D11: 280
A12: P10 | B12: Creatine Monohydrate 250g | C12: Performance | D12: 390

Sheet orders
A1: Table: orders | B1: 50 records
A2: order_id | B2: customer_id | C2: order_date | D2: order_status | E2: total_amount | F2: coupon_code | G2: ProperDate | H2: Month_Name | I2: OrderPlaced(Ago) | J2: Flag Orders
A3: ORD001 | B3: C001 | C3: 2024-01-05 | D3: Delivered | E3: 2450 | F3: NEWYEAR10 | G3: =text(datevalue(C3),"dd-mm-yyyy") -> 05-01-2024 | H3: =text(DATEVALUE(C3),"mmmm") -> January | I3: =today()-Datevalue(C3) -> 822 | J3: =if(I3="","",if(today()-datevalue(G3)>180,"Archive","Active")) -> Archive
A4: ORD002 | B4: C002 | C4: 2024-01-08 | D4: Delivered | E4: 1890 | G4: =text(datevalue(C4),"dd-mm-yyyy") -> 08-01-2024 | H4: =text(DATEVALUE(C4),"mmmm") -> January | I4: =today()-Datevalue(C4) -> 819 | J4: =if(I4="","",if(today()-datevalue(G4)>180,"Archive","Active")) -> Archive
A5: ORD003 | B5: C003 | C5: 2024-01-12 | D5: Delivered | E5: 3200 | F5: WELCOME15 | G5: =text(datevalue(C5),"dd-mm-yyyy") -> 12-01-2024 | H5: =text(DATEVALUE(C5),"mmmm") -> January | I5: =today()-Datevalue(C5) -> 815 | J5: =if(I5="","",if(today()-datevalue(G5)>180,"Archive","Active")) -> Archive
A6: ORD004 | B6: C001 | C6: 2024-01-20 | D6: Delivered | E6: 980 | G6: =text(datevalue(C6),"dd-mm-yyyy") -> 20-01-2024 | H6: =text(DATEVALUE(C6),"mmmm") -> January | I6: =today()-Datevalue(C6) -> 807 | J6: =if(I6="","",if(today()-datevalue(G6)>180,"Archive","Active")) -> Archive
A7: ORD005 | B7: C004 | C7: 2024-01-25 | D7: Returned | E7: 1540 | F7: FLAT100 | G7: =text(datevalue(C7),"dd-mm-yyyy") -> 25-01-2024 | H7: =text(DATEVALUE(C7),"mmmm") -> January | I7: =today()-Datevalue(C7) -> 802 | J7: =if(I7="","",if(today()-datevalue(G7)>180,"Archive","Active")) -> Archive
A8: ORD006 | B8: C005 | C8: 2024-02-02 | D8: Delivered | E8: 2100 | G8: =text(datevalue(C8),"dd-mm-yyyy") -> 02-02-2024 | H8: =text(DATEVALUE(C8),"mmmm") -> February | I8: =today()-Datevalue(C8) -> 794 | J8: =if(I8="","",if(today()-datevalue(G8)>180,"Archive","Active")) -> Archive
A9: ORD007 | B9: C006 | C9: 2024-02-05 | D9: Delivered | E9: 870 | G9: =text(datevalue(C9),"dd-mm-yyyy") -> 05-02-2024 | H9: =text(DATEVALUE(C9),"mmmm") -> February | I9: =today()-Datevalue(C9) -> 791 | J9: =if(I9="","",if(today()-datevalue(G9)>180,"Archive","Active")) -> Archive
A10: ORD008 | B10: C003 | C10: 2024-02-10 | D10: Delivered | E10: 1650 | F10: SAVE10 | G10: =text(datevalue(C10),"dd-mm-yyyy") -> 10-02-2024 | H10: =text(DATEVALUE(C10),"mmmm") -> February | I10: =today()-Datevalue(C10) -> 786 | J10: =if(I10="","",if(today()-datevalue(G10)>180,"Archive","Active")) -> Archive
A11: ORD009 | B11: C007 | C11: 2024-02-14 | D11: Delivered | E11: 3400 | G11: =text(datevalue(C11),"dd-mm-yyyy") -> 14-02-2024 | H11: =text(DATEVALUE(C11),"mmmm") -> February | I11: =today()-Datevalue(C11) -> 782 | J11: =if(I11="","",if(today()-datevalue(G11)>180,"Archive","Active")) -> Archive
A12: ORD010 | B12: C002 | C12: 2024-02-18 | D12: Cancelled | E12: 760 | G12: =text(datevalue(C12),"dd-mm-yyyy") -> 18-02-2024 | H12: =text(DATEVALUE(C12),"mmmm") -> February | I12: =today()-Datevalue(C12) -> 778 | J12: =if(I12="","",if(today()-datevalue(G12)>180,"Archive","Active")) -> Archive
A13: ORD011 | B13: C008 | C13: 2024-02-22 | D13: Delivered | E13: 1200 | F13: FLAT100 | G13: =text(datevalue(C13),"dd-mm-yyyy") -> 22-02-2024 | H13: =text(DATEVALUE(C13),"mmmm") -> February | I13: =today()-Datevalue(C13) -> 774 | J13: =if(I13="","",if(today()-datevalue(G13)>180,"Archive","Active")) -> Archive
A14: ORD012 | B14: C005 | C14: 2024-03-01 | D14: Delivered | E14: 2800 | G14: =text(datevalue(C14),"dd-mm-yyyy") -> 01-03-2024 | H14: =text(DATEVALUE(C14),"mmmm") -> March | I14: =today()-Datevalue(C14) -> 766 | J14: =if(I14="","",if(today()-datevalue(G14)>180,"Archive","Active")) -> Archive
A15: ORD013 | B15: C009 | C15: 2024-03-05 | D15: Delivered | E15: 1430 | G15: =text(datevalue(C15),"dd-mm-yyyy") -> 05-03-2024 | H15: =text(DATEVALUE(C15),"mmmm") -> March | I15: =today()-Datevalue(C15) -> 762 | J15: =if(I15="","",if(today()-datevalue(G15)>180,"Archive","Active")) -> Archive
A16: ORD014 | B16: C001 | C16: 2024-03-09 | D16: Delivered | E16: 2100 | F16: MARCH20 | G16: =text(datevalue(C16),"dd-mm-yyyy") -> 09-03-2024 | H16: =text(DATEVALUE(C16),"mmmm") -> March | I16: =today()-Datevalue(C16) -> 758 | J16: =if(I16="","",if(today()-datevalue(G16)>180,"Archive","Active")) -> Archive
A17: ORD015 | B17: C010 | C17: 2024-03-15 | D17: Returned | E17: 990 | G17: =text(datevalue(C17),"dd-mm-yyyy") -> 15-03-2024 | H17: =text(DATEVALUE(C17),"mmmm") -> March | I17: =today()-Datevalue(C17) -> 752 | J17: =if(I17="","",if(today()-datevalue(G17)>180,"Archive","Active")) -> Archive
A18: ORD016 | B18: C006 | C18: 2024-03-20 | D18: Delivered | E18: 1760 | G18: =text(datevalue(C18),"dd-mm-yyyy") -> 20-03-2024 | H18: =text(DATEVALUE(C18),"mmmm") -> March | I18: =today()-Datevalue(C18) -> 747 | J18: =if(I18="","",if(today()-datevalue(G18)>180,"Archive","Active")) -> Archive
A19: ORD017 | B19: C011 | C19: 2024-03-25 | D19: Delivered | E19: 3100 | F19: WELCOME15 | G19: =text(datevalue(C19),"dd-mm-yyyy") -> 25-03-2024 | H19: =text(DATEVALUE(C19),"mmmm") -> March | I19: =today()-Datevalue(C19) -> 742 | J19: =if(I19="","",if(today()-datevalue(G19)>180,"Archive","Active")) -> Archive
A20: ORD018 | B20: C004 | C20: 2024-04-02 | D20: Delivered | E20: 2450 | G20: =text(datevalue(C20),"dd-mm-yyyy") -> 02-04-2024 | H20: =text(DATEVALUE(C20),"mmmm") -> April | I20: =today()-Datevalue(C20) -> 734 | J20: =if(I20="","",if(today()-datevalue(G20)>180,"Archive","Active")) -> Archive
A21: ORD019 | B21: C012 | C21: 2024-04-07 | D21: Delivered | E21: 1300 | G21: =text(datevalue(C21),"dd-mm-yyyy") -> 07-04-2024 | H21: =text(DATEVALUE(C21),"mmmm") -> April | I21: =today()-Datevalue(C21) -> 729 | J21: =if(I21="","",if(today()-datevalue(G21)>180,"Archive","Active")) -> Archive
A22: ORD020 | B22: C007 | C22: 2024-04-11 | D22: Delivered | E22: 2900 | F22: SAVE10 | G22: =text(datevalue(C22),"dd-mm-yyyy") -> 11-04-2024 | H22: =text(DATEVALUE(C22),"mmmm") -> April | I22: =today()-Datevalue(C22) -> 725 | J22: =if(I22="","",if(today()-datevalue(G22)>180,"Archive","Active")) -> Archive
A23: ORD021 | B23: C013 | C23: 2024-04-16 | D23: Delivered | E23: 880 | G23: =text(datevalue(C23),"dd-mm-yyyy") -> 16-04-2024 | H23: =text(DATEVALUE(C23),"mmmm") -> April | I23: =today()-Datevalue(C23) -> 720 | J23: =if(I23="","",if(today()-datevalue(G23)>180,"Archive","Active")) -> Archive
A24: ORD022 | B24: C003 | C24: 2024-04-20 | D24: Delivered | E24: 1550 | G24: =text(datevalue(C24),"dd-mm-yyyy") -> 20-04-2024 | H24: =text(DATEVALUE(C24),"mmmm") -> April | I24: =today()-Datevalue(C24) -> 716 | J24: =if(I24="","",if(today()-datevalue(G24)>180,"Archive","Active")) -> Archive
A25: ORD023 | B25: C008 | C25: 2024-04-25 | D25: Cancelled | E25: 640 | G25: =text(datevalue(C25),"dd-mm-yyyy") -> 25-04-2024 | H25: =text(DATEVALUE(C25),"mmmm") -> April | I25: =today()-Datevalue(C25) -> 711 | J25: =if(I25="","",if(today()-datevalue(G25)>180,"Archive","Active")) -> Archive
A26: ORD024 | B26: C014 | C26: 2024-05-03 | D26: Delivered | E26: 2200 | F26: MAY10 | G26: =text(datevalue(C26),"dd-mm-yyyy") -> 03-05-2024 | H26: =text(DATEVALUE(C26),"mmmm") -> May | I26: =today()-Datevalue(C26) -> 703 | J26: =if(I26="","",if(today()-datevalue(G26)>180,"Archive","Active")) -> Archive
A27: ORD025 | B27: C005 | C27: 2024-05-08 | D27: Delivered | E27: 3600 | G27: =text(datevalue(C27),"dd-mm-yyyy") -> 08-05-2024 | H27: =text(DATEVALUE(C27),"mmmm") -> May | I27: =today()-Datevalue(C27) -> 698 | J27: =if(I27="","",if(today()-datevalue(G27)>180,"Archive","Active")) -> Archive
A28: ORD026 | B28: C015 | C28: 2024-05-12 | D28: Delivered | E28: 1470 | G28: =text(datevalue(C28),"dd-mm-yyyy") -> 12-05-2024 | H28: =text(DATEVALUE(C28),"mmmm") -> May | I28: =today()-Datevalue(C28) -> 694 | J28: =if(I28="","",if(today()-datevalue(G28)>180,"Archive","Active")) -> Archive
A29: ORD027 | B29: C002 | C29: 2024-05-16 | D29: Delivered | E29: 2050 | G29: =text(datevalue(C29),"dd-mm-yyyy") -> 16-05-2024 | H29: =text(DATEVALUE(C29),"mmmm") -> May | I29: =today()-Datevalue(C29) -> 690 | J29: =if(I29="","",if(today()-datevalue(G29)>180,"Archive","Active")) -> Archive
A30: ORD028 | B30: C011 | C30: 2024-05-20 | D30: Delivered | E30: 1900 | F30: FLAT100 | G30: =text(datevalue(C30),"dd-mm-yyyy") -> 20-05-2024 | H30: =text(DATEVALUE(C30),"mmmm") -> May | I30: =today()-Datevalue(C30) -> 686 | J30: =if(I30="","",if(today()-datevalue(G30)>180,"Archive","Active")) -> Archive
A31: ORD029 | B31: C009 | C31: 2024-05-25 | D31: Returned | E31: 830 | G31: =text(datevalue(C31),"dd-mm-yyyy") -> 25-05-2024 | H31: =text(DATEVALUE(C31),"mmmm") -> May | I31: =today()-Datevalue(C31) -> 681 | J31: =if(I31="","",if(today()-datevalue(G31)>180,"Archive","Active")) -> Archive
A32: ORD030 | B32: C016 | C32: 2024-06-01 | D32: Delivered | E32: 2650 | G32: =text(datevalue(C32),"dd-mm-yyyy") -> 01-06-2024 | H32: =text(DATEVALUE(C32),"mmmm") -> June | I32: =today()-Datevalue(C32) -> 674 | J32: =if(I32="","",if(today()-datevalue(G32)>180,"Archive","Active")) -> Archive
A33: ORD031 | B33: C001 | C33: 2024-06-05 | D33: Delivered | E33: 1780 | F33: JUNE15 | G33: =text(datevalue(C33),"dd-mm-yyyy") -> 05-06-2024 | H33: =text(DATEVALUE(C33),"mmmm") -> June | I33: =today()-Datevalue(C33) -> 670 | J33: =if(I33="","",if(today()-datevalue(G33)>180,"Archive","Active")) -> Archive
A34: ORD032 | B34: C006 | C34: 2024-06-10 | D34: Delivered | E34: 3100 | G34: =text(datevalue(C34),"dd-mm-yyyy") -> 10-06-2024 | H34: =text(DATEVALUE(C34),"mmmm") -> June | I34: =today()-Datevalue(C34) -> 665 | J34: =if(I34="","",if(today()-datevalue(G34)>180,"Archive","Active")) -> Archive
A35: ORD033 | B35: C017 | C35: 2024-06-14 | D35: Delivered | E35: 1230 | G35: =text(datevalue(C35),"dd-mm-yyyy") -> 14-06-2024 | H35: =text(DATEVALUE(C35),"mmmm") -> June | I35: =today()-Datevalue(C35) -> 661 | J35: =if(I35="","",if(today()-datevalue(G35)>180,"Archive","Active")) -> Archive
A36: ORD034 | B36: C010 | C36: 2024-06-18 | D36: Delivered | E36: 2800 | G36: =text(datevalue(C36),"dd-mm-yyyy") -> 18-06-2024 | H36: =text(DATEVALUE(C36),"mmmm") -> June | I36: =today()-Datevalue(C36) -> 657 | J36: =if(I36="","",if(today()-datevalue(G36)>180,"Archive","Active")) -> Archive
A37: ORD035 | B37: C013 | C37: 2024-06-22 | D37: Delivered | E37: 1650 | G37: =text(datevalue(C37),"dd-mm-yyyy") -> 22-06-2024 | H37: =text(DATEVALUE(C37),"mmmm") -> June | I37: =today()-Datevalue(C37) -> 653 | J37: =if(I37="","",if(today()-datevalue(G37)>180,"Archive","Active")) -> Archive
A38: ORD036 | B38: C003 | C38: 2024-07-01 | D38: Delivered | E38: 2400 | G38: =text(datevalue(C38),"dd-mm-yyyy") -> 01-07-2024 | H38: =text(DATEVALUE(C38),"mmmm") -> July | I38: =today()-Datevalue(C38) -> 644 | J38: =if(I38="","",if(today()-datevalue(G38)>180,"Archive","Active")) -> Archive
A39: ORD037 | B39: C018 | C39: 2024-07-05 | D39: Delivered | E39: 1100 | G39: =text(datevalue(C39),"dd-mm-yyyy") -> 05-07-2024 | H39: =text(DATEVALUE(C39),"mmmm") -> July | I39: =today()-Datevalue(C39) -> 640 | J39: =if(I39="","",if(today()-datevalue(G39)>180,"Archive","Active")) -> Archive
A40: ORD038 | B40: C012 | C40: 2024-07-09 | D40: Cancelled | E40: 760 | G40: =text(datevalue(C40),"dd-mm-yyyy") -> 09-07-2024 | H40: =text(DATEVALUE(C40),"mmmm") -> July | I40: =today()-Datevalue(C40) -> 636 | J40: =if(I40="","",if(today()-datevalue(G40)>180,"Archive","Active")) -> Archive
...

Sheet LOOKUP
A2: ORDER ID | B2: ORD001
A4: Customer Name | B4: City | C4: Order Status | D4: Total Amount | E4: Complaint Type
A5: {=if(B2="","",xlookup(xlookup(B2,orders!A2:A52,orders!B2:B52),customers!A3:A22,customers!B3:C22))} -> Priya Sharma | B5: Mumbai | C5: {=if(B2="","", xlookup(B2,orders!A3:A52,orders!D3:E52))} -> Delivered | D5: 2450 | E5: {=if(B2="","", xlookup(B2,complaints!B3:B24,complaints!C3:C24,"No Complaint"))} -> No Complaint

Sheet Q4.1

Sheet order_items
A1: Table: order_items | B1: ~100 records · 1-3 items per order
A2: order_id | B2: product_id | C2: quantity | D2: unit_price | E2: Revenue
A3: ORD001 | B3: P01 | C3: 1 | D3: 1899 | E3: =C3*D3 -> 1899
A4: ORD001 | B4: P02 | C4: 1 | D4: 599 | E4: =C4*D4 -> 599
A5: ORD001 | B5: P09 | C5: 1 | D5: 449 | E5: =C5*D5 -> 449
A6: ORD002 | B6: P03 | C6: 2 | D6: 799 | E6: =C6*D6 -> 1598
A7: ORD002 | B7: P06 | C7: 1 | D7: 349 | E7: =C7*D7 -> 349
A8: ORD003 | B8: P04 | C8: 1 | D8: 1999 | E8: =C8*D8 -> 1999
A9: ORD003 | B9: P07 | C9: 1 | D9: 1199 | E9: =C9*D9 -> 1199
A10: ORD004 | B10: P10 | C10: 2 | D10: 499 | E10: =C10*D10 -> 998
A11: ORD005 | B11: P05 | C11: 1 | D11: 849 | E11: =C11*D11 -> 849
A12: ORD005 | B12: P02 | C12: 1 | D12: 599 | E12: =C12*D12 -> 599
A13: ORD006 | B13: P01 | C13: 1 | D13: 1899 | E13: =C13*D13 -> 1899
A14: ORD006 | B14: P03 | C14: 1 | D14: 799 | E14: =C14*D14 -> 799
... A107: ORD050 | B107: P07 | C107: 1 | D107: 1199 | E107: =C107*D107 -> 1199

Sheet Pivot Table 2

Sheet complaints
A1: Table: complaints | B1: 22 records
A2: complaint_id | B2: order_id | C2: complaint_type | D2: raised_date | E2: resolved_date | F2: courier_partner
A3: CMP001 | B3: ORD002 | C3: Late Delivery | D3: 2024-01-15 | E3: 2024-01-18 | F3: BlueDart
A4: CMP002 | B4: ORD005 | C4: Wrong Item | D4: 2024-01-28 | E4: 2024-02-01 | F4: Delhivery
A5: CMP003 | B5: ORD007 | C5: Damaged Product | D5: 2024-02-08 | E5: 2024-02-12 | F5: Ekart
A6: CMP004 | B6: ORD010 | C6: Late Delivery | D6: 2024-02-21 | E6: 2024-02-24 | F6: BlueDart
A7: CMP005 | B7: ORD012 | C7: Missing Item | D7: 2024-03-05 | E7: 2024-03-09 | F7: Delhivery
A8: CMP006 | B8: ORD015 | C8: Wrong Item | D8: 2024-03-18 | E8: 2024-03-22 | F8: Ekart
A9: CMP007 | B9: ORD017 | C9: Late Delivery | D9: 2024-03-28 | E9: 2024-04-01 | F9: BlueDart
A10: CMP008 | B10: ORD019 | C10: Damaged Product | D10: 2024-04-10 | E10: 2024-04-15 | F10: Delhivery
A11: CMP009 | B11: ORD021 | C11: Late Delivery | D11: 2024-04-19 | E11: 2024-04-21 | F11: Ekart
A12: CMP010 | B12: ORD023 | C12: Missing Item | D12: 2024-04-27 | E12: 2024-04-30 | F12: BlueDart
A13: CMP011 | B13: ORD026 | C13: Late Delivery | D13: 2024-05-15 | E13: 2024-05-19 | F13: Delhivery
... A24: CMP022 | B24: ORD049 | C24: Late Delivery | D24: 2024-09-04 | E24: 2024-09-07 | F24: BlueDart

Sheet FilteredCustomer
A1: customer_id | B1: name | C1: city | D1: acquisition_channel | E1: signup_date | F1: Total_Spend | G1: Status
A2: =IFERROR(__xludf.DUMMYFUNCTION("sort(FILTER(customers!A2:E22, REGEXMATCH(LOWER(customers!C2:C22), ""ahmedabad|mumbai"") * (customers!E2:E22>date(2023,1,1))),5,True)"),"C003") -> C003 | B2: =IFERROR(__xludf.DUMMYFUNCTION("""COMPUTED_VALUE"""),"Anita Joshi") -> Anita Joshi | C2: =IFERROR(__xludf.DUMMYFUNCTION("""COMPUTED_VALUE"""),"Ahmedabad") -> Ahmedabad | D2: =IFERROR(__xludf.DUMMYFUNCTION("""COMPUTED_VALUE"""),"Referral") -> Referral | E2: =IFERROR(__xludf.DUMMYFUNCTION("""COMPUTED_VALUE"""),"2023-01-20") -> 2023-01-20 | F2: =SUMIFS(orders!E:E,orders!B:B,A2) -> 8800 | G2: =if(F2>5000,"High Value","Standard") -> High Value
A3: =IFERROR(__xludf.DUMMYFUNCTION("""COMPUTED_VALUE"""),"C001") -> C001 | B3: =IFERROR(__xludf.DUMMYFUNCTION("""COMPUTED_VALUE"""),"Priya Sharma") -> Priya Sharma | C3: =IFERROR(__xludf.DUMMYFUNCTION("""COMPUTED_VALUE"""),"Mumbai") -> Mumbai | D3: =IFERROR(__xludf.DUMMYFUNCTION("""COMPUTED_VALUE"""),"Google Ads") -> Google Ads | E3: =IFERROR(__xludf.DUMMYFUNCTION("""COMPUTED_VALUE"""),"2023-03-15") -> 2023-03-15 | F3: =SUMIFS(orders!E:E,orders!B:B,A3) -> 10710 | G3: =if(F3>5000,"High Value","Standard") -> High Value
A4: =IFERROR(__xludf.DUMMYFUNCTION("""COMPUTED_VALUE"""),"C011") -> C011 | B4: =IFERROR(__xludf.DUMMYFUNCTION("""COMPUTED_VALUE"""),"Nidhi Shah") -> Nidhi Shah | C4: =IFERROR(__xludf.DUMMYFUNCTION("""COMPUTED_VALUE"""),"Ahmedabad") -> Ahmedabad | D4: =IFERROR(__xludf.DUMMYFUNCTION("""COMPUTED_VALUE"""),"Organic Search") -> Organic Search | E4: =IFERROR(__xludf.DUMMYFUNCTION("""COMPUTED_VALUE"""),"2023-11-22") -> 2023-11-22 | F4: =SUMIFS(orders!E:E,orders!B:B,A4) -> 7100 | G4: =if(F4>5000,"High Value","Standard") -> High Value
A5: =IFERROR(__xludf.DUMMYFUNCTION("""COMPUTED_VALUE"""),"C012") -> C012 | B5: =IFERROR(__xludf.DUMMYFUNCTION("""COMPUTED_VALUE"""),"Rahul Verma") -> Rahul Verma | C5: =IFERROR(__xludf.DUMMYFUNCTION("""COMPUTED_VALUE"""),"Mumbai") -> Mumbai | D5: =IFERROR(__xludf.DUMMYFUNCTION("""COMPUTED_VALUE"""),"Instagram") -> Instagram | E5: =IFERROR(__xludf.DUMMYFUNCTION("""COMPUTED_VALUE"""),"2023-12-10") -> 2023-12-10 | F5: =SUMIFS(orders!E:E,orders!B:B,A5) -> 2060 | G5: =if(F5>5000,"High Value","Standard") -> Standard
A6: =IFERROR(__xludf.DUMMYFUNCTION("""COMPUTED_VALUE"""),"C017") -> C017 | B6: =IFERROR(__xludf.DUMMYFUNCTION("""COMPUTED_VALUE"""),"Sonal Dave") -> Sonal Dave | C6: =IFERROR(__xludf.DUMMYFUNCTION("""COMPUTED_VALUE"""),"Ahmedabad") -> Ahmedabad | D6: =IFERROR(__xludf.DUMMYFUNCTION("""COMPUTED_VALUE"""),"Referral") -> Referral | E6: =IFERROR(__xludf.DUMMYFUNCTION("""COMPUTED_VALUE"""),"2024-04-15") -> 2024-04-15 | F6: =SUMIFS(orders!E:E,orders!B:B,A6) -> 2680 | G6: =if(F6>5000,"High Value","Standard") -> Standard
A7: =IFERROR(__xludf.DUMMYFUNCTION("""COMPUTED_VALUE"""),"C020") -> C020 | B7: =IFERROR(__xludf.DUMMYFUNCTION("""COMPUTED_VALUE"""),"Farhan Sheikh") -> Farhan Sheikh | C7: =IFERROR(__xludf.DUMMYFUNCTION("""COMPUTED_VALUE"""),"Mumbai") -> Mumbai | D7: =IFERROR(__xludf.DUMMYFUNCTION("""COMPUTED_VALUE"""),"Instagram") -> Instagram | E7: =IFERROR(__xludf.DUMMYFUNCTION("""COMPUTED_VALUE"""),"2024-06-01") -> 2024-06-01 | F7: =SUMIFS(orders!E:E,orders!B:B,A7) -> 2100 | G7: =if(F7>5000,"High Value","Standard") -> Standard

Sheet UpdatedOrders
A1: order_id | B1: customer_id | C1: order_date | D1: order_status | E1: total_amount | F1: coupon_code | G1: City
A2: ORD001 | B2: C001 | C2: 2024-01-05 | D2: Delivered | E2: 2450 | F2: NEWYEAR10 | G2: {=xlookup(B2,customers!A:A,customers!C:C)} -> Mumbai
A3: ORD002 | B3: C002 | C3: 2024-01-08 | D3: Delivered | E3: 1890 | G3: {=xlookup(B3,customers!A:A,customers!C:C)} -> Delhi
A4: ORD003 | B4: C003 | C4: 2024-01-12 | D4: Delivered | E4: 3200 | F4: WELCOME15 | G4: {=xlookup(B4,customers!A:A,customers!C:C)} -> Ahmedabad
A5: ORD004 | B5: C001 | C5: 2024-01-20 | D5: Delivered | E5: 980 | G5: {=xlookup(B5,customers!A:A,customers!C:C)} -> Mumbai
A6: ORD005 | B6: C004 | C6: 2024-01-25 | D6: Returned | E6: 1540 | F6: FLAT100 | G6: {=xlookup(B6,customers!A:A,customers!C:C)} -> Surat
A7: ORD006 | B7: C005 | C7: 2024-02-02 | D7: Delivered | E7: 2100 | G7: {=xlookup(B7,customers!A:A,customers!C:C)} -> Bangalore
A8: ORD007 | B8: C006 | C8: 2024-02-05 | D8: Delivered | E8: 870 | G8: {=xlookup(B8,customers!A:A,customers!C:C)} -> Chennai
A9: ORD008 | B9: C003 | C9: 2024-02-10 | D9: Delivered | E9: 1650 | F9: SAVE10 | G9: {=xlookup(B9,customers!A:A,customers!C:C)} -> Ahmedabad
A10: ORD009 | B10: C007 | C10: 2024-02-14 | D10: Delivered | E10: 3400 | G10: {=xlookup(B10,customers!A:A,customers!C:C)} -> Hyderabad
A11: ORD010 | B11: C002 | C11: 2024-02-18 | D11: Cancelled | E11: 760 | G11: {=xlookup(B11,customers!A:A,customers!C:C)} -> Delhi
A12: ORD011 | B12: C008 | C12: 2024-02-22 | D12: Delivered | E12: 1200 | F12: FLAT100 | G12: {=xlookup(B12,customers!A:A,customers!C:C)} -> Pune
A13: ORD012 | B13: C005 | C13: 2024-03-01 | D13: Delivered | E13: 2800 | G13: {=xlookup(B13,customers!A:A,customers!C:C)} -> Bangalore
A14: ORD013 | B14: C009 | C14: 2024-03-05 | D14: Delivered | E14: 1430 | G14: {=xlookup(B14,customers!A:A,customers!C:C)} -> Kochi
A15: ORD014 | B15: C001 | C15: 2024-03-09 | D15: Delivered | E15: 2100 | F15: MARCH20 | G15: {=xlookup(B15,customers!A:A,customers!C:C)} -> Mumbai
A16: ORD015 | B16: C010 | C16: 2024-03-15 | D16: Returned | E16: 990 | G16: {=xlookup(B16,customers!A:A,customers!C:C)} -> Jaipur
A17: ORD016 | B17: C006 | C17: 2024-03-20 | D17: Delivered | E17: 1760 | G17: {=xlookup(B17,customers!A:A,customers!C:C)} -> Chennai
A18: ORD017 | B18: C011 | C18: 2024-03-25 | D18: Delivered | E18: 3100 | F18: WELCOME15 | G18: {=xlookup(B18,customers!A:A,customers!C:C)} -> Ahmedabad
A19: ORD018 | B19: C004 | C19: 2024-04-02 | D19: Delivered | E19: 2450 | G19: {=xlookup(B19,customers!A:A,customers!C:C)} -> Surat
A20: ORD019 | B20: C012 | C20: 2024-04-07 | D20: Delivered | E20: 1300 | G20: {=xlookup(B20,customers!A:A,customers!C:C)} -> Mumbai
A21: ORD020 | B21: C007 | C21: 2024-04-11 | D21: Delivered | E21: 2900 | F21: SAVE10 | G21: {=xlookup(B21,customers!A:A,customers!C:C)} -> Hyderabad
A22: ORD021 | B22: C013 | C22: 2024-04-16 | D22: Delivered | E22: 880 | G22: {=xlookup(B22,customers!A:A,customers!C:C)} -> Delhi
A23: ORD022 | B23: C003 | C23: 2024-04-20 | D23: Delivered | E23: 1550 | G23: {=xlookup(B23,customers!A:A,customers!C:C)} -> Ahmedabad
A24: ORD023 | B24: C008 | C24: 2024-04-25 | D24: Cancelled | E24: 640 | G24: {=xlookup(B24,customers!A:A,customers!C:C)} -> Pune
A25: ORD024 | B25: C014 | C25: 2024-05-03 | D25: Delivered | E25: 2200 | F25: MAY10 | G25: {=xlookup(B25,customers!A:A,customers!C:C)} -> Surat
A26: ORD025 | B26: C005 | C26: 2024-05-08 | D26: Delivered | E26: 3600 | G26: {=xlookup(B26,customers!A:A,customers!C:C)} -> Bangalore
A27: ORD026 | B27: C015 | C27: 2024-05-12 | D27: Delivered | E27: 1470 | G27: {=xlookup(B27,customers!A:A,customers!C:C)} -> Bangalore
A28: ORD027 | B28: C002 | C28: 2024-05-16 | D28: Delivered | E28: 2050 | G28: {=xlookup(B28,customers!A:A,customers!C:C)} -> Delhi
A29: ORD028 | B29: C011 | C29: 2024-05-20 | D29: Delivered | E29: 1900 | F29: FLAT100 | G29: {=xlookup(B29,customers!A:A,customers!C:C)} -> Ahmedabad
A30: ORD029 | B30: C009 | C30: 2024-05-25 | D30: Returned | E30: 830 | G30: {=xlookup(B30,customers!A:A,customers!C:C)} -> Kochi
A31: ORD030 | B31: C016 | C31: 2024-06-01 | D31: Delivered | E31: 2650 | G31: {=xlookup(B31,customers!A:A,customers!C:C)} -> Hyderabad
A32: ORD031 | B32: C001 | C32: 2024-06-05 | D32: Delivered | E32: 1780 | F32: JUNE15 | G32: {=xlookup(B32,customers!A:A,customers!C:C)} -> Mumbai
A33: ORD032 | B33: C006 | C33: 2024-06-10 | D33: Delivered | E33: 3100 | G33: {=xlookup(B33,customers!A:A,customers!C:C)} -> Chennai
A34: ORD033 | B34: C017 | C34: 2024-06-14 | D34: Delivered | E34: 1230 | G34: {=xlookup(B34,customers!A:A,customers!C:C)} -> Ahmedabad
A35: ORD034 | B35: C010 | C35: 2024-06-18 | D35: Delivered | E35: 2800 | G35: {=xlookup(B35,customers!A:A,customers!C:C)} -> Jaipur
A36: ORD035 | B36: C013 | C36: 2024-06-22 | D36: Delivered | E36: 1650 | G36: {=xlookup(B36,customers!A:A,customers!C:C)} -> Delhi
A37: ORD036 | B37: C003 | C37: 2024-07-01 | D37: Delivered | E37: 2400 | G37: {=xlookup(B37,customers!A:A,customers!C:C)} -> Ahmedabad
A38: ORD037 | B38: C018 | C38: 2024-07-05 | D38: Delivered | E38: 1100 | G38: {=xlookup(B38,customers!A:A,customers!C:C)} -> Lucknow
A39: ORD038 | B39: C012 | C39: 2024-07-09 | D39: Cancelled | E39: 760 | G39: {=xlookup(B39,customers!A:A,customers!C:C)} -> Mumbai
A40: ORD039 | B40: C007 | C40: 2024-07-14 | D40: Delivered | E40: 2980 | G40: {=xlookup(B40,customers!A:A,customers!C:C)} -> Hyderabad
...

Sheet Dashboard

Sheet DynamicDashboard
B1: Total Revenue | C1: Total Orders | D1: Average Order Value | E1: Delivery %
B2: =sumif(UpdatedOrders!G:G,A3,UpdatedOrders!E:E) -> 0 | C2: =countif(UpdatedOrders!G3:G1001,A3) -> 0 | D2: =IFERROR(B2/C2,0) -> 0 | E2: =countifs(UpdatedOrders!G:G,A3,UpdatedOrders!D:D,"Delivered")/countif(UpdatedOrders!G:G,A3) -> 0
A3: city

Sheet Sheet5
